Workbook

Sheet Proyecciones
B2: Costos Iniciales | E2: Capital Financiado por Socios (40%) | F2: =C9*0.4 -> 21735329 | H2: # Landings | I2: Costos Totales | J2: Costo medio/Unitario | K2: Utilidad Operativa | L2: M1 | M2: P1 | N2: Utilidad Neta antes de Tx | O2: M2 | P2: P2 | Q2: Utilidad Neta después de Tx | R2: Carga Impositiva | S2: M3 | T2: P3 | U2: U1 | V2: P4 | W2: Recuperación en Meses | Y2: Discriminación compras de equipos (IVA 19%)
B3: Imprevistos | C3: =0.075*C8 -> 1890622.5 | H3: 34 | I3: =$C$56+H3*$C$59 -> 26551300 | J3: =I3/H3 -> 780920.59 | K3: =$C$61*H3-I3 -> 308700 | L3: =(K3)/I3 -> 0.011626549 | M3: =I3*(1+L3)/H3 -> 790000 | N3: =K3-$F$9 -> -788383.5 | O3: =(N3)/(I3+$F$9) -> -0.028514633 | P3: =(I3+$F$9)*(O3+1)/H3 -> 790000 | Q3: =N3*(1-$F$42) -> -512449.28 | R3: =$F$42*N3 -> -275934.23 | S3: =Q3/(I3+$F$9+R3) -> -0.018721353 | T3: =((I3+$F$9)*(1-$F$42))*(S3+1)/(H3*((1-$F$42)-S3*$F$42)) -> 790000 | U3: =($C$61-J3)/$C$61 -> 0.011492926 | V3: =I3/(H3*(1-U3)) -> 790000 | W3: =$C$9/K3 -> 176.02307 | Y3: Concepto | Z3: Total bruto | AA3: Base | AB3: IVA
B4: Registro de Cámara y Comercio | C4: =24220+8477*53795200/1000000 -> 480241.91 | E4: Gastos Financieros (60%) - Bancolombia Libre Inversión | H4: 35 | I4: =$C$56+H4*$C$59 -> 26590800 | J4: =I4/H4 -> 759737.14 | K4: =$C$61*H4-I4 -> 1059200 | L4: =(K4)/I4 -> 0.039833326 | M4: =I4*(1+L4)/H4 -> 790000 | N4: =K4-$F$9 -> -37883.504 | O4: =(N4)/(I4+$F$9) -> -0.001368234 | P4: =(I4+$F$9)*(O4+1)/H4 -> 790000 | Q4: =N4*(1-$F$42) -> -24624.278 | R4: =$F$42*N4 -> -13259.226 | S4: =Q4/(I4+$F$9+R4) -> -0.0008897782 | T4: =((I4+$F$9)*(1-$F$42))*(S4+1)/(H4*((1-$F$42)-S4*$F$42)) -> 790000 | U4: =($C$61-J4)/$C$61 -> 0.038307414 | V4: =I4/(H4*(1-U4)) -> 790000 | W4: =$C$9/K4 -> 51.301286 | Y4: Portátiles | Z4: =C5 -> 26039400 | AA4: =Z4/1.19 -> 21881849 | AB4: =Z4-AA4 -> 4157551.3
B5: Lenovo ThinkPad E14 Gen7 (x6) | C5: =4339900*6 -> 26039400 | E5: Valor Presente | F5: =C9*0.6 -> 32602994 | H5: 36 | I5: =$C$56+H5*$C$59 -> 26630300 | J5: =I5/H5 -> 739730.56 | K5: =$C$61*H5-I5 -> 1809700 | L5: =(K5)/I5 -> 0.067956426 | M5: =I5*(1+L5)/H5 -> 790000 | N5: =K5-$F$9 -> 712616.5 | O5: =(N5)/(I5+$F$9) -> 0.02570082 | P5: =(I5+$F$9)*(O5+1)/H5 -> 790000 | Q5: =N5*(1-$F$42) -> 463200.72 | R5: =$F$42*N5 -> 249415.77 | S5: =Q5/(I5+$F$9+R5) -> 0.016556602 | T5: =((I5+$F$9)*(1-$F$42))*(S5+1)/(H5*((1-$F$42)-S5*$F$42)) -> 790000 | U5: =($C$61-J5)/$C$61 -> 0.063632208 | V5: =I5/(H5*(1-U5)) -> 790000 | W5: =$C$9/K5 -> 30.026149 | Y5: Mouses | Z5: =C6 -> 150000 | AA5: =Z5/1.19 -> 126050.42 | AB5: =Z5-AA5 -> 23949.58
B6: Mouse Ergonómico (x6) | C6: =25000*6 -> 150000 | E6: Tasa EA | F6: 0.137 | H6: 37 | I6: =$C$56+H6*$C$59 -> 26669800 | J6: =I6/H6 -> 720805.41 | K6: =$C$61*H6-I6 -> 2560200 | L6: =(K6)/I6 -> 0.09599622 | M6: =I6*(1+L6)/H6 -> 790000 | N6: =K6-$F$9 -> 1463116.5 | O6: =(N6)/(I6+$F$9) -> 0.05269286 | P6: =(I6+$F$9)*(O6+1)/H6 -> 790000 | Q6: =N6*(1-$F$42) -> 951025.72 | R6: =$F$42*N6 -> 512090.77 | S6: =Q6/(I6+$F$9+R6) -> 0.033630135 | T6: =((I6+$F$9)*(1-$F$42))*(S6+1)/(H6*((1-$F$42)-S6*$F$42)) -> 790000 | U6: =($C$61-J6)/$C$61 -> 0.087588094 | V6: =I6/(H6*(1-U6)) -> 790000 | W6: =$C$9/K6 -> 21.224249 | Y6: Monitores | Z6: =C7 -> 1050000 | AA6: =Z6/1.19 -> 882352.94 | AB6: =Z6-AA6 -> 167647.06
B7: Monitor Extensible (x3) | C7: =350000*3 -> 1050000 | E7: Tasa Mensual | F7: =(1+F6)^(1/12)-1 -> 0.010756878 | H7: 38 | I7: =$C$56+H7*$C$59 -> 26709300 | J7: =I7/H7 -> 702876.32 | K7: =$C$61*H7-I7 -> 3310700 | L7: =(K7)/I7 -> 0.12395308 | M7: =I7*(1+L7)/H7 -> 790000 | N7: =K7-$F$9 -> 2213616.5 | O7: =(N7)/(I7+$F$9) -> 0.079608213 | P7: =(I7+$F$9)*(O7+1)/H7 -> 790000 | Q7: =N7*(1-$F$42) -> 1438850.7 | R7: =$F$42*N7 -> 774765.77 | S7: =Q7/(I7+$F$9+R7) -> 0.050342647 | T7: =((I7+$F$9)*(1-$F$42))*(S7+1)/(H7*((1-$F$42)-S7*$F$42)) -> 790000 | U7: =($C$61-J7)/$C$61 -> 0.11028314 | V7: =I7/(H7*(1-U7)) -> 790000 | W7: =$C$9/K7 -> 16.412941 | Y7: Totales | Z7: =SUM(Z4:Z6) -> 27239400 | AA7: =SUM(AA4:AA6) -> 22890252 | AB7: =SUM(AB4:AB6) -> 4349147.9
B8: Primer Mes de Costos Fijos | C8: =C56 -> 25208300 | E8: Plazo en Meses | F8: 36 | H8: 39 | I8: =$C$56+H8*$C$59 -> 26748800 | J8: =I8/H8 -> 685866.67 | K8: =$C$61*H8-I8 -> 4061200 | L8: =(K8)/I8 -> 0.15182737 | M8: =I8*(1+L8)/H8 -> 790000 | N8: =K8-$F$9 -> 2964116.5 | O8: =(N8)/(I8+$F$9) -> 0.10644721 | P8: =(I8+$F$9)*(O8+1)/H8 -> 790000 | Q8: =N8*(1-$F$42) -> 1926675.7 | R8: =$F$42*N8 -> 1037440.8 | S8: =Q8/(I8+$F$9+R8) -> 0.06670547 | T8: =((I8+$F$9)*(1-$F$42))*(S8+1)/(H8*((1-$F$42)-S8*$F$42)) -> 790000 | U8: =($C$61-J8)/$C$61 -> 0.13181435 | V8: =I8/(H8*(1-U8)) -> 790000 | W8: =$C$9/K8 -> 13.379869
B9: Total Costos iniciales | C9: =SUM(C3:C8)-C4 -> 54338322 | E9: Cuota mensual | F9: =PMT(F7,F8,-F5) -> 1097083.5 | H9: 40 | I9: =$C$56+H9*$C$59 -> 26788300 | J9: =I9/H9 -> 669707.5 | K9: =$C$61*H9-I9 -> 4811700 | L9: =(K9)/I9 -> 0.17961946 | M9: =I9*(1+L9)/H9 -> 790000 | N9: =K9-$F$9 -> 3714616.5 | O9: =(N9)/(I9+$F$9) -> 0.13321016 | P9: =(I9+$F$9)*(O9+1)/H9 -> 790000 | Q9: =N9*(1-$F$42) -> 2414500.7 | R9: =$F$42*N9 -> 1300115.8 | S9: =Q9/(I9+$F$9+R9) -> 0.082729464 | T9: =((I9+$F$9)*(1-$F$42))*(S9+1)/(H9*((1-$F$42)-S9*$F$42)) -> 790000 | U9: =($C$61-J9)/$C$61 -> 0.15226899 | V9: =I9/(H9*(1-U9)) -> 790000 | W9: =$C$9/K9 -> 11.292957
E10: Valor Futuro | F10: =F9*F8 -> 39495006 | H10: 41 | I10: =$C$56+H10*$C$59 -> 26827800 | J10: =I10/H10 -> 654336.59 | K10: =$C$61*H10-I10 -> 5562200 | L10: =(K10)/I10 -> 0.20732971 | M10: =I10*(1+L10)/H10 -> 790000 | N10: =K10-$F$9 -> 4465116.5 | O10: =(N10)/(I10+$F$9) -> 0.15989741 | P10: =(I10+$F$9)*(O10+1)/H10 -> 790000 | Q10: =N10*(1-$F$42) -> 2902325.7 | R10: =$F$42*N10 -> 1562790.8 | S10: =Q10/(I10+$F$9+R10) -> 0.098425047 | T10: =((I10+$F$9)*(1-$F$42))*(S10+1)/(H10*((1-$F$42)-S10*$F$42)) -> 790000 | U10: =($C$61-J10)/$C$61 -> 0.17172584 | V10: =I10/(H10*(1-U10)) -> 790000 | W10: =$C$9/K10 -> 9.7692141 | Y10: Resumen mensual abril - diciembre 2026
B11: Costos fijos Mensuales | H11: 42 | I11: =$C$56+H11*$C$59 -> 26867300 | J11: =I11/H11 -> 639697.62 | K11: =$C$61*H11-I11 -> 6312700 | L11: =(K11)/I11 -> 0.23495848 | M11: =I11*(1+L11)/H11 -> 790000 | N11: =K11-$F$9 -> 5215616.5 | O11: =(N11)/(I11+$F$9) -> 0.18650926 | P11: =(I11+$F$9)*(O11+1)/H11 -> 790000 | Q11: =N11*(1-$F$42) -> 3390150.7 | R11: =$F$42*N11 -> 1825465.8 | S11: =Q11/(I11+$F$9+R11) -> 0.11380221 | T11: =((I11+$F$9)*(1-$F$42))*(S11+1)/(H11*((1-$F$42)-S11*$F$42)) -> 790000 | U11: =($C$61-J11)/$C$61 -> 0.19025618 | V11: =I11/(H11*(1-U11)) -> 790000 | W11: =$C$9/K11 -> 8.6077784 | Y11: Concepto | Z11: Abril | AA11: Mayo | AB11: Junio | AC11: Julio | AD11: Agosto | AE11: Septiembre | AF11: Octubre | AG11: Noviembre | AH11: Diciembre
B12: Dominio Propio .com | C12: 5000 | E12: Gastos Financieros (60%) - Bancamia Microcrédito | H12: 43 | I12: =$C$56+H12*$C$59 -> 26906800 | J12: =I12/H12 -> 625739.53 | K12: =$C$61*H12-I12 -> 7063200 | L12: =(K12)/I12 -> 0.26250613 | M12: =I12*(1+L12)/H12 -> 790000 | N12: =K12-$F$9 -> 5966116.5 | O12: =(N12)/(I12+$F$9) -> 0.21304604 | P12: =(I12+$F$9)*(O12+1)/H12 -> 790000 | Q12: =N12*(1-$F$42) -> 3877975.7 | R12: =$F$42*N12 -> 2088140.8 | S12: =Q12/(I12+$F$9+R12) -> 0.12887055 | T12: =((I12+$F$9)*(1-$F$42))*(S12+1)/(H12*((1-$F$42)-S12*$F$42)) -> 790000 | U12: =($C$61-J12)/$C$61 -> 0.20792464 | V12: =I12/(H12*(1-U12)) -> 790000 | W12: =$C$9/K12 -> 7.6931593 | Y12: Unidades vendidas | Z12: 0 | AA12: 45 | AB12: 45 | AC12: 45 | AD12: 45 | AE12: 45 | AF12: 45 | AG12: 45 | AH12: 45
B13: Host de Correo profesional | C13: 10000 | E13: Valor Presente | F13: =C9*0.6 -> 32602994 | H13: 44 | I13: =$C$56+H13*$C$59 -> 26946300 | J13: =I13/H13 -> 612415.91 | K13: =$C$61*H13-I13 -> 7813700 | L13: =(K13)/I13 -> 0.28997302 | M13: =I13*(1+L13)/H13 -> 790000 | N13: =K13-$F$9 -> 6716616.5 | O13: =(N13)/(I13+$F$9) -> 0.23950806 | P13: =(I13+$F$9)*(O13+1)/H13 -> 790000 | Q13: =N13*(1-$F$42) -> 4365800.7 | R13: =$F$42*N13 -> 2350815.8 | S13: =Q13/(I13+$F$9+R13) -> 0.14363927 | T13: =((I13+$F$9)*(1-$F$42))*(S13+1)/(H13*((1-$F$42)-S13*$F$42)) -> 790000 | U13: =($C$61-J13)/$C$61 -> 0.22478999 | V13: =I13/(H13*(1-U13)) -> 790000 | W13: =$C$9/K13 -> 6.9542371 | Y13: Ingresos operacionales | Z13: =Z12*$C$61 -> 0 | AA13: =AA12*$C$61 -> 35550000 | AB13: =AB12*$C$61 -> 35550000 | AC13: =AC12*$C$61 -> 35550000 | AD13: =AD12*$C$61 -> 35550000 | AE13: =AE12*$C$61 -> 35550000 | AF13: =AF12*$C$61 -> 35550000 | AG13: =AG12*$C$61 -> 35550000 | AH13: =AH12*$C$61 -> 35550000
B14: GitHub Enterprice | C14: 40000 | E14: Tasa EA | F14: 0.34 | H14: # Landings | I14: Costos Totales | J14: Costo medio/Unitario | K14: Utilidad Operativa | L14: M1 | M14: P1 | N14: Utilidad Neta antes de Tx | O14: M2 | P14: P2 | Q14: Utilidad Neta después de Tx | R14: Carga Impositiva | S14: M3 | T14: P3 | U14: U1 | V14: P4 | W14: Recuperación en Meses | Y14: Costos fijos | Z14: =$C$56 -> 25208300 | AA14: =$C$56 -> 25208300 | AB14: =$C$56 -> 25208300 | AC14: =$C$56 -> 25208300 | AD14: =$C$56 -> 25208300 | AE14: =$C$56 -> 25208300 | AF14: =$C$56 -> 25208300 | AG14: =$C$56 -> 25208300 | AH14: =$C$56 -> 25208300
B15: Publicidad | C15: 1500000 | E15: Tasa Mensual | F15: =(1+F14)^(1/12)-1 -> 0.024688982 | H15: 45 | I15: =$C$56+H15*$C$59 -> 26985800 | J15: =I15/H15 -> 599684.44 | K15: =$C$61*H15-I15 -> 8564200 | L15: =(K15)/I15 -> 0.3173595 | M15: =I15*(1+L15)/H15 -> 790000 | N15: =K15-$F$9 -> 7467116.5 | O15: =(N15)/(I15+$F$9) -> 0.26589565 | P15: =(I15+$F$9)*(O15+1)/H15 -> 790000 | Q15: =N15*(1-$F$42) -> 4853625.7 | R15: =$F$42*N15 -> 2613490.8 | S15: =Q15/(I15+$F$9+R15) -> 0.15811723 | T15: =((I15+$F$9)*(1-$F$42))*(S15+1)/(H15*((1-$F$42)-S15*$F$42)) -> 790000 | U15: =($C$61-J15)/$C$61 -> 0.24090577 | V15: =I15/(H15*(1-U15)) -> 790000 | W15: =$C$9/K15 -> 6.3448218 | Y15: Costos variables | Z15: =Z12*$C$59 -> 0 | AA15: =AA12*$C$59 -> 1777500 | AB15: =AB12*$C$59 -> 1777500 | AC15: =AC12*$C$59 -> 1777500 | AD15: =AD12*$C$59 -> 1777500 | AE15: =AE12*$C$59 -> 1777500 | AF15: =AF12*$C$59 -> 1777500 | AG15: =AG12*$C$59 -> 1777500 | AH15: =AH12*$C$59 -> 1777500
B16: Programadores (x3) | E16: Plazo en Meses | F16: 36 | H16: 46 | I16: =$C$56+H16*$C$59 -> 27025300 | J16: =I16/H16 -> 587506.52 | K16: =$C$61*H16-I16 -> 9314700 | L16: =(K16)/I16 -> 0.34466592 | M16: =I16*(1+L16)/H16 -> 790000 | N16: =K16-$F$9 -> 8217616.5 | O16: =(N16)/(I16+$F$9) -> 0.2922091 | P16: =(I16+$F$9)*(O16+1)/H16 -> 790000 | Q16: =N16*(1-$F$42) -> 5341450.7 | R16: =$F$42*N16 -> 2876165.8 | S16: =Q16/(I16+$F$9+R16) -> 0.17231293 | T16: =((I16+$F$9)*(1-$F$42))*(S16+1)/(H16*((1-$F$42)-S16*$F$42)) -> 790000 | U16: =($C$61-J16)/$C$61 -> 0.25632086 | V16: =I16/(H16*(1-U16)) -> 790000 | W16: =$C$9/K16 -> 5.8336095 | Y16: Intereses crédito Bancolombia | Z16: 0 | AA16: =L27 -> 350706.43 | AB16: =L28 -> 342677.74 | AC16: =L29 -> 334562.69 | AD16: =L30 -> 326360.35 | AE16: =L31 -> 318069.77 | AF16: =L32 -> 309690.02 | AG16: =L33 -> 301220.12 | AH16: =L34 -> 292659.12
B17: Salarios Base | C17: 9000000 | E17: Cuota mensual | F17: =PMT(F15,F16,-F13) -> 1377392.2 | H17: 47 | I17: =$C$56+H17*$C$59 -> 27064800 | J17: =I17/H17 -> 575846.81 | K17: =$C$61*H17-I17 -> 10065200 | L17: =(K17)/I17 -> 0.37189264 | M17: =I17*(1+L17)/H17 -> 790000 | N17: =K17-$F$9 -> 8968116.5 | O17: =(N17)/(I17+$F$9) -> 0.31844875 | P17: =(I17+$F$9)*(O17+1)/H17 -> 790000 | Q17: =N17*(1-$F$42) -> 5829275.7 | R17: =$F$42*N17 -> 3138840.8 | S17: =Q17/(I17+$F$9+R17) -> 0.18623453 | T17: =((I17+$F$9)*(1-$F$42))*(S17+1)/(H17*((1-$F$42)-S17*$F$42)) -> 790000 | U17: =($C$61-J17)/$C$61 -> 0.27107999 | V17: =I17/(H17*(1-U17)) -> 790000 | W17: =$C$9/K17 -> 5.3986332 | Y17: Abono a capital crédito | Z17: 0 | AA17: =M27 -> 746377.07 | AB17: =M28 -> 754405.76 | AC17: =M29 -> 762520.81 | AD17: =M30 -> 770723.16 | AE17: =M31 -> 779013.73 | AF17: =M32 -> 787393.49 | AG17: =M33 -> 795863.38 | AH17: =M34 -> 804424.39
B18: Auxilios de conectividad | C18: 750000 | E18: Valor Futuro | F18: =F17*F16 -> 49586119 | H18: 48 | I18: =$C$56+H18*$C$59 -> 27104300 | J18: =I18/H18 -> 564672.92 | K18: =$C$61*H18-I18 -> 10815700 | L18: =(K18)/I18 -> 0.39904 | M18: =I18*(1+L18)/H18 -> 790000 | N18: =K18-$F$9 -> 9718616.5 | O18: =(N18)/(I18+$F$9) -> 0.34461488 | P18: =(I18+$F$9)*(O18+1)/H18 -> 790000 | Q18: =N18*(1-$F$42) -> 6317100.7 | R18: =$F$42*N18 -> 3401515.8 | S18: =Q18/(I18+$F$9+R18) -> 0.19988991 | T18: =((I18+$F$9)*(1-$F$42))*(S18+1)/(H18*((1-$F$42)-S18*$F$42)) -> 790000 | U18: =($C$61-J18)/$C$61 -> 0.28522416 | V18: =I18/(H18*(1-U18)) -> 790000 | W18: =$C$9/K18 -> 5.0240227 | Y18: Cuota crédito Bancolombia | Z18: =Z16+Z17 -> 0 | AA18: =AA16+AA17 -> 1097083.5 | AB18: =AB16+AB17 -> 1097083.5 | AC18: =AC16+AC17 -> 1097083.5 | AD18: =AD16+AD17 -> 1097083.5 | AE18: =AE16+AE17 -> 1097083.5 | AF18: =AF16+AF17 -> 1097083.5 | AG18: =AG16+AG17 -> 1097083.5 | AH18: =AH16+AH17 -> 1097083.5
B19: Primas Amortizadas | C19: 750000 | H19: 49 | I19: =$C$56+H19*$C$59 -> 27143800 | J19: =I19/H19 -> 553955.1 | K19: =$C$61*H19-I19 -> 11566200 | L19: =(K19)/I19 -> 0.42610836 | M19: =I19*(1+L19)/H19 -> 790000 | N19: =K19-$F$9 -> 10469116 | O19: =(N19)/(I19+$F$9) -> 0.37070782 | P19: =(I19+$F$9)*(O19+1)/H19 -> 790000 | Q19: =N19*(1-$F$42) -> 6804925.7 | R19: =$F$42*N19 -> 3664190.8 | S19: =Q19/(I19+$F$9+R19) -> 0.21328663 | T19: =((I19+$F$9)*(1-$F$42))*(S19+1)/(H19*((1-$F$42)-S19*$F$42)) -> 790000 | U19: =($C$61-J19)/$C$61 -> 0.29879101 | V19: =I19/(H19*(1-U19)) -> 790000 | W19: =$C$9/K19 -> 4.6980272 | Y19: Resultado antes de impuestos | Z19: =Z13-Z14-Z15-Z16 -> -25208300 | AA19: =AA13-AA14-AA15-AA16 -> 8213493.6 | AB19: =AB13-AB14-AB15-AB16 -> 8221522.3 | AC19: =AC13-AC14-AC15-AC16 -> 8229637.3 | AD19: =AD13-AD14-AD15-AD16 -> 8237839.7 | AE19: =AE13-AE14-AE15-AE16 -> 8246130.2 | AF19: =AF13-AF14-AF15-AF16 -> 8254510 | AG19: =AG13-AG14-AG15-AG16 -> 8262979.9 | AH19: =AH13-AH14-AH15-AH16 -> 8271540.9
B20: Cesantías amortizadas | C20: 750000 | E20: Gastos Financieros (60%) - SENA Mejor Caso | H20: 50 | I20: =$C$56+H20*$C$59 -> 27183300 | J20: =I20/H20 -> 543666 | K20: =$C$61*H20-I20 -> 12316700 | L20: =(K20)/I20 -> 0.45309804 | M20: =I20*(1+L20)/H20 -> 790000 | N20: =K20-$F$9 -> 11219616 | O20: =(N20)/(I20+$F$9) -> 0.39672788 | P20: =(I20+$F$9)*(O20+1)/H20 -> 790000 | Q20: =N20*(1-$F$42) -> 7292750.7 | R20: =$F$42*N20 -> 3926865.8 | S20: =Q20/(I20+$F$9+R20) -> 0.22643196 | T20: =((I20+$F$9)*(1-$F$42))*(S20+1)/(H20*((1-$F$42)-S20*$F$42)) -> 790000 | U20: =($C$61-J20)/$C$61 -> 0.31181519 | V20: =I20/(H20*(1-U20)) -> 790000 | W20: =$C$9/K20 -> 4.4117598 | Y20: Impuesto de renta | Z20: 0 | AA20: 0 | AB20: 0 | AC20: 0 | AD20: 0 | AE20: 0 | AF20: 0 | AG20: 0 | AH20: =IF(SUM(Z19:AH19)>0,SUM(Z19:AH19)*$F$42,0) -> 14255274
B21: Interés a las cesantías | C21: 90000 | E21: Valor Presente | F21: =C9*0.6 -> 32602994 | H21: 51 | I21: =$C$56+H21*$C$59 -> 27222800 | J21: =I21/H21 -> 533780.39 | K21: =$C$61*H21-I21 -> 13067200 | L21: =(K21)/I21 -> 0.4800094 | M21: =I21*(1+L21)/H21 -> 790000 | N21: =K21-$F$9 -> 11970116 | O21: =(N21)/(I21+$F$9) -> 0.42267534 | P21: =(I21+$F$9)*(O21+1)/H21 -> 790000 | Q21: =N21*(1-$F$42) -> 7780575.7 | R21: =$F$42*N21 -> 4189540.8 | S21: =Q21/(I21+$F$9+R21) -> 0.23933293 | T21: =((I21+$F$9)*(1-$F$42))*(S21+1)/(H21*((1-$F$42)-S21*$F$42)) -> 790000 | U21: =($C$61-J21)/$C$61 -> 0.32432862 | V21: =I21/(H21*(1-U21)) -> 790000 | W21: =$C$9/K21 -> 4.1583754 | Y21: Resultado neto | Z21: =Z19-Z20 -> -25208300 | AA21: =AA19-AA20 -> 8213493.6 | AB21: =AB19-AB20 -> 8221522.3 | AC21: =AC19-AC20 -> 8229637.3 | AD21: =AD19-AD20 -> 8237839.7 | AE21: =AE19-AE20 -> 8246130.2 | AF21: =AF19-AF20 -> 8254510 | AG21: =AG19-AG20 -> 8262979.9 | AH21: =AH19-AH20 -> -5983732.9
B22: Salud (8.5% Zumia) | C22: =C17*0.085 -> 765000 | E22: Tasa EA | F22: 0.08 | H22: 52 | I22: =$C$56+H22*$C$59 -> 27262300 | J22: =I22/H22 -> 524275 | K22: =$C$61*H22-I22 -> 13817700 | L22: =(K22)/I22 -> 0.50684278 | M22: =I22*(1+L22)/H22 -> 790000 | N22: =K22-$F$9 -> 12720616 | O22: =(N22)/(I22+$F$9) -> 0.44855053 | P22: =(I22+$F$9)*(O22+1)/H22 -> 790000 | Q22: =N22*(1-$F$42) -> 8268400.7 | R22: =$F$42*N22 -> 4452215.8 | S22: =Q22/(I22+$F$9+R22) -> 0.25199627 | T22: =((I22+$F$9)*(1-$F$42))*(S22+1)/(H22*((1-$F$42)-S22*$F$42)) -> 790000 | U22: =($C$61-J22)/$C$61 -> 0.33636076 | V22: =I22/(H22*(1-U22)) -> 790000 | W22: =$C$9/K22 -> 3.9325157 | Y22: Flujo de caja del mes | Z22: =$F$2+$F$5-$C$3-$C$5-$C$6-$C$7-$C$8 -> 0 | AA22: =AA13-AA14-AA15-AA18 -> 7467116.5 | AB22: =AB13-AB14-AB15-AB18 -> 7467116.5 | AC22: =AC13-AC14-AC15-AC18 -> 7467116.5 | AD22: =AD13-AD14-AD15-AD18 -> 7467116.5 | AE22: =AE13-AE14-AE15-AE18 -> 7467116.5 | AF22: =AF13-AF14-AF15-AF18 -> 7467116.5 | AG22: =AG13-AG14-AG15-AG18 -> 7467116.5 | AH22: =AH13-AH14-AH15-AH18-AH20 -> -6788157.3
B23: ARL clase I (0.522%) | C23: =C17*0.00522 -> 46980 | E23: Tasa Mensual | F23: =(1+F22)^(1/12)-1 -> 0.0064340301 | H23: 53 | I23: =$C$56+H23*$C$59 -> 27301800 | J23: =I23/H23 -> 515128.3 | K23: =$C$61*H23-I23 -> 14568200 | L23: =(K23)/I23 -> 0.53359852 | M23: =I23*(1+L23)/H23 -> 790000 | N23: =K23-$F$9 -> 13471116 | O23: =(N23)/(I23+$F$9) -> 0.47435374 | P23: =(I23+$F$9)*(O23+1)/H23 -> 790000 | Q23: =N23*(1-$F$42) -> 8756225.7 | R23: =$F$42*N23 -> 4714890.8 | S23: =Q23/(I23+$F$9+R23) -> 0.2644285 | T23: =((I23+$F$9)*(1-$F$42))*(S23+1)/(H23*((1-$F$42)-S23*$F$42)) -> 790000 | U23: =($C$61-J23)/$C$61 -> 0.34793886 | V23: =I23/(H23*(1-U23)) -> 790000 | W23: =$C$9/K23 -> 3.729927 | Y23: Saldo de caja acumulado | Z23: =Z22 -> 0 | AA23: =Z23+AA22 -> 7467116.5 | AB23: =AA23+AB22 -> 14934233 | AC23: =AB23+AC22 -> 22401349 | AD23: =AC23+AD22 -> 29868466 | AE23: =AD23+AE22 -> 37335582 | AF23: =AE23+AF22 -> 44802699 | AG23: =AF23+AG22 -> 52269815 | AH23: =AG23+AH22 -> 45481658
B24: Pensión (12% Zumia) | C24: =C17*0.12 -> 1080000 | E24: Plazo en Meses | F24: 36 | H24: 54 | I24: =$C$56+H24*$C$59 -> 27341300 | J24: =I24/H24 -> 506320.37 | K24: =$C$61*H24-I24 -> 15318700 | L24: =(K24)/I24 -> 0.56027694 | M24: =I24*(1+L24)/H24 -> 790000 | N24: =K24-$F$9 -> 14221616 | O24: =(N24)/(I24+$F$9) -> 0.50008526 | P24: =(I24+$F$9)*(O24+1)/H24 -> 790000 | Q24: =N24*(1-$F$42) -> 9244050.7 | R24: =$F$42*N24 -> 4977565.8 | S24: =Q24/(I24+$F$9+R24) -> 0.27663589 | T24: =((I24+$F$9)*(1-$F$42))*(S24+1)/(H24*((1-$F$42)-S24*$F$42)) -> 790000 | U24: =($C$61-J24)/$C$61 -> 0.35908814 | V24: =I24/(H24*(1-U24)) -> 790000 | W24: =$C$9/K24 -> 3.5471889
B25: Parafiscales (Caja, ICBF, SENA) | C25: =C17*0.09 -> 810000 | E25: Cuota mensual | F25: =PMT(F23,F24,-F21) -> 1017465.8
B26: Gerente | E26: Valor Futuro | F26: =F25*F24 -> 36628768 | H26: Bancolombia | I26: Mes operación | J26: Saldo inicial | K26: Cuota pagada | L26: Interés | M26: Abono a capital | N26: Saldo final | O26: Estado al M9 | P26: Promedio Restante | Q26: Mes operación | R26: Saldo inicial | S26: Cuota pagada | T26: Interés | U26: Abono a capital | V26: Saldo final | W26: Estado al M9
B27: Salarios Base | C27: 2000000 | H27: 1 | I27: 2 | J27: =F5 -> 32602994 | K27: =$F$9 -> 1097083.5 | L27: =J27*$F$7 -> 350706.43 | M27: =K27-L27 -> 746377.07 | N27: =J27-M27 -> 31856616 | O27: Pagada | P27: 1 | Q27: 2 | R27: =C9*0.6 -> 32602994 | S27: =PMT(AVERAGE(F15,F23,F31,(1+F37)^(1/12)-1,(1+F38)^(1/12)-1,(1+F39)^(1/12)-1,(1+F40)^(1/12)-1), 36, -R27) -> 1157921.2 | T27: =R27*(AVERAGE($F$15,$F$23,$F$31,(1+$F$37)^(1/12)-1,(1+$F$38)^(1/12)-1,(1+$F$39)^(1/12)-1,(1+$F$40)^(1/12)-1)) -> 454392.15 | U27: =S27-T27 -> 703529.05 | V27: =R27-U27 -> 31899464 | W27: Pagada
B28: Auxilios de conectividad | C28: 250000 | E28: Gastos Financieros (60%) - SENA Peor Caso | H28: 2 | I28: 3 | J28: =N27 -> 31856616 | K28: =$F$9 -> 1097083.5 | L28: =J28*$F$7 -> 342677.74 | M28: =K28-L28 -> 754405.76 | N28: =J28-M28 -> 31102211 | O28: Pagada | P28: 2 | Q28: 3 | R28: =V27 -> 31899464 | S28: =$S$27 -> 1157921.2 | T28: =R28*(AVERAGE($F$15,$F$23,$F$31,(1+$F$37)^(1/12)-1,(1+$F$38)^(1/12)-1,(1+$F$39)^(1/12)-1,(1+$F$40)^(1/12)-1)) -> 444586.97 | U28: =S28-T28 -> 713334.23 | V28: =R28-U28 -> 31186130 | W28: Pagada
B29: Primas Amortizadas | C29: =C27/12 -> 166666.67 | E29: Valor Presente | F29: =C9*0.6 -> 32602994 | H29: 3 | I29: 4 | J29: =N28 -> 31102211 | K29: =$F$9 -> 1097083.5 | L29: =J29*$F$7 -> 334562.69 | M29: =K29-L29 -> 762520.81 | N29: =J29-M29 -> 30339690 | O29: Pagada | P29: 3 | Q29: 4 | R29: =V28 -> 31186130 | S29: =$S$27 -> 1157921.2 | T29: =R29*(AVERAGE($F$15,$F$23,$F$31,(1+$F$37)^(1/12)-1,(1+$F$38)^(1/12)-1,(1+$F$39)^(1/12)-1,(1+$F$40)^(1/12)-1)) -> 434645.14 | U29: =S29-T29 -> 723276.06 | V29: =R29-U29 -> 30462854 | W29: Pagada
B30: Cesantías amortizadas | C30: =C27/12 -> 166666.67 | E30: Tasa EA | F30: 0.17 | H30: 4 | I30: 5 | J30: =N29 -> 30339690 | K30: =$F$9 -> 1097083.5 | L30: =J30*$F$7 -> 326360.35 | M30: =K30-L30 -> 770723.16 | N30: =J30-M30 -> 29568967 | O30: Pagada | P30: 4 | Q30: 5 | R30: =V29 -> 30462854 | S30: =$S$27 -> 1157921.2 | T30: =R30*(AVERAGE($F$15,$F$23,$F$31,(1+$F$37)^(1/12)-1,(1+$F$38)^(1/12)-1,(1+$F$39)^(1/12)-1,(1+$F$40)^(1/12)-1)) -> 424564.75 | U30: =S30-T30 -> 733356.45 | V30: =R30-U30 -> 29729498 | W30: Pagada
B31: Interés a las cesantías | C31: 20000 | E31: Tasa Mensual | F31: =(1+F30)^(1/12)-1 -> 0.013169611 | H31: 5 | I31: 6 | J31: =N30 -> 29568967 | K31: =$F$9 -> 1097083.5 | L31: =J31*$F$7 -> 318069.77 | M31: =K31-L31 -> 779013.73 | N31: =J31-M31 -> 28789953 | O31: Pagada | P31: 5 | Q31: 6 | R31: =V30 -> 29729498 | S31: =$S$27 -> 1157921.2 | T31: =R31*(AVERAGE($F$15,$F$23,$F$31,(1+$F$37)^(1/12)-1,(1+$F$38)^(1/12)-1,(1+$F$39)^(1/12)-1,(1+$F$40)^(1/12)-1)) -> 414343.86 | U31: =S31-T31 -> 743577.34 | V31: =R31-U31 -> 28985920 | W31: Pagada
B32: Salud (8.5% Zumia) | C32: =C27*0.085 -> 170000 | E32: Plazo en Meses | F32: 36 | H32: 6 | I32: 7 | J32: =N31 -> 28789953 | K32: =$F$9 -> 1097083.5 | L32: =J32*$F$7 -> 309690.02 | M32: =K32-L32 -> 787393.49 | N32: =J32-M32 -> 28002559 | O32: Pagada | P32: 6 | Q32: 7 | R32: =V31 -> 28985920 | S32: =$S$27 -> 1157921.2 | T32: =R32*(AVERAGE($F$15,$F$23,$F$31,(1+$F$37)^(1/12)-1,(1+$F$38)^(1/12)-1,(1+$F$39)^(1/12)-1,(1+$F$40)^(1/12)-1)) -> 403980.53 | U32: =S32-T32 -> 753940.67 | V32: =R32-U32 -> 28231980 | W32: Pagada
B33: ARL clase I (0.522%) | C33: =C27*0.00522 -> 10440 | E33: Cuota mensual | F33: =PMT(F31,F32,-F29) -> 1143064.7 | H33: 7 | I33: 8 | J33: =N32 -> 28002559 | K33: =$F$9 -> 1097083.5 | L33: =J33*$F$7 -> 301220.12 | M33: =K33-L33 -> 795863.38 | N33: =J33-M33 -> 27206696 | O33: Pagada | P33: 7 | Q33: 8 | R33: =V32 -> 28231980 | S33: =$S$27 -> 1157921.2 | T33: =R33*(AVERAGE($F$15,$F$23,$F$31,(1+$F$37)^(1/12)-1,(1+$F$38)^(1/12)-1,(1+$F$39)^(1/12)-1,(1+$F$40)^(1/12)-1)) -> 393472.76 | U33: =S33-T33 -> 764448.44 | V33: =R33-U33 -> 27467531 | W33: Pagada
B34: Pensión (12% Zumia) | C34: =C27*0.12 -> 240000 | E34: Valor Futuro | F34: =F33*F32 -> 41150328 | H34: 8 | I34: 9 | J34: =N33 -> 27206696 | K34: =$F$9 -> 1097083.5 | L34: =J34*$F$7 -> 292659.12 | M34: =K34-L34 -> 804424.39 | N34: =J34-M34 -> 26402272 | O34: Pagada | P34: 8 | Q34: 9 | R34: =V33 -> 27467531 | S34: =$S$27 -> 1157921.2 | T34: =R34*(AVERAGE($F$15,$F$23,$F$31,(1+$F$37)^(1/12)-1,(1+$F$38)^(1/12)-1,(1+$F$39)^(1/12)-1,(1+$F$40)^(1/12)-1)) -> 382818.54 | U34: =S34-T34 -> 775102.66 | V34: =R34-U34 -> 26692429 | W34: Pagada
B35: Parafiscales (Caja, ICBF, SENA) | C35: =C27*0.09 -> 180000 | H35: 9 | I35: 10 | J35: =N34 -> 26402272 | K35: =$F$9 -> 1097083.5 | L35: =J35*$F$7 -> 284006.02 | M35: =K35-L35 -> 813077.48 | N35: =J35-M35 -> 25589194 | O35: Pendiente | P35: 9 | Q35: 10 | R35: =V34 -> 26692429 | S35: =$S$27 -> 1157921.2 | T35: =R35*(AVERAGE($F$15,$F$23,$F$31,(1+$F$37)^(1/12)-1,(1+$F$38)^(1/12)-1,(1+$F$39)^(1/12)-1,(1+$F$40)^(1/12)-1)) -> 372015.84 | U35: =S35-T35 -> 785905.36 | V35: =R35-U35 -> 25906523 | W35: Pendiente
B36: Contador | E36: Otras Opciones de financiación EA - Libre inversión | H36: 10 | I36: 11 | J36: =N35 -> 25589194 | K36: =$F$9 -> 1097083.5 | L36: =J36*$F$7 -> 275259.85 | M36: =K36-L36 -> 821823.66 | N36: =J36-M36 -> 24767371 | O36: Pendiente | P36: 10 | Q36: 11 | R36: =V35 -> 25906523 | S36: =$S$27 -> 1157921.2 | T36: =R36*(AVERAGE($F$15,$F$23,$F$31,(1+$F$37)^(1/12)-1,(1+$F$38)^(1/12)-1,(1+$F$39)^(1/12)-1,(1+$F$40)^(1/12)-1)) -> 361062.57 | U36: =S36-T36 -> 796858.63 | V36: =R36-U36 -> 25109665 | W36: Pendiente
B37: Salarios Base | C37: 2000000 | E37: Banco de Bogotá | F37: 0.1388 | H37: 11 | I37: 12 | J37: =N36 -> 24767371 | K37: =$F$9 -> 1097083.5 | L37: =J37*$F$7 -> 266419.59 | M37: =K37-L37 -> 830663.92 | N37: =J37-M37 -> 23936707 | O37: Pendiente | P37: 11 | Q37: 12 | R37: =V36 -> 25109665 | S37: =$S$27 -> 1157921.2 | T37: =R37*(AVERAGE($F$15,$F$23,$F$31,(1+$F$37)^(1/12)-1,(1+$F$38)^(1/12)-1,(1+$F$39)^(1/12)-1,(1+$F$40)^(1/12)-1)) -> 349956.65 | U37: =S37-T37 -> 807964.55 | V37: =R37-U37 -> 24301700 | W37: Pendiente
B38: Auxilios de conectividad | C38: 250000 | E38: BBVA | F38: 0.175 | H38: 12 | I38: 13 | J38: =N37 -> 23936707 | K38: =$F$9 -> 1097083.5 | L38: =J38*$F$7 -> 257484.24 | M38: =K38-L38 -> 839599.27 | N38: =J38-M38 -> 23097107 | O38: Pendiente | P38: 12 | Q38: 13 | R38: =V37 -> 24301700 | S38: =$S$27 -> 1157921.2 | T38: =R38*(AVERAGE($F$15,$F$23,$F$31,(1+$F$37)^(1/12)-1,(1+$F$38)^(1/12)-1,(1+$F$39)^(1/12)-1,(1+$F$40)^(1/12)-1)) -> 338695.94 | U38: =S38-T38 -> 819225.26 | V38: =R38-U38 -> 23482475 | W38: Pendiente
B39: Primas Amortizadas | C39: =C37/12 -> 166666.67 | E39: DAVIVIENDA | F39: 0.185 | H39: 13 | I39: 14 | J39: =N38 -> 23097107 | K39: =$F$9 -> 1097083.5 | L39: =J39*$F$7 -> 248452.77 | M39: =K39-L39 -> 848630.73 | N39: =J39-M39 -> 22248477 | O39: Pendiente | P39: 13 | Q39: 14 | R39: =V38 -> 23482475 | S39: =$S$27 -> 1157921.2 | T39: =R39*(AVERAGE($F$15,$F$23,$F$31,(1+$F$37)^(1/12)-1,(1+$F$38)^(1/12)-1,(1+$F$39)^(1/12)-1,(1+$F$40)^(1/12)-1)) -> 327278.29 | U39: =S39-T39 -> 830642.91 | V39: =R39-U39 -> 22651832 | W39: Pendiente
B40: Cesantías amortizadas | C40: =C37/12 -> 166666.67 | E40: PICHINCHA | F40: 0.19 | H40: 14 | I40: 15 | J40: =N39 -> 22248477 | K40: =$F$9 -> 1097083.5 | L40: =J40*$F$7 -> 239324.15 | M40: =K40-L40 -> 857759.35 | N40: =J40-M40 -> 21390717 | O40: Pendiente | P40: 14 | Q40: 15 | R40: =V39 -> 22651832 | S40: =$S$27 -> 1157921.2 | T40: =R40*(AVERAGE($F$15,$F$23,$F$31,(1+$F$37)^(1/12)-1,(1+$F$38)^(1/12)-1,(1+$F$39)^(1/12)-1,(1+$F$40)^(1/12)-1)) -> 315701.52 | U40: =S40-T40 -> 842219.68 | V40: =R40-U40 -> 21809612 | W40: Pendiente
B41: Interés a las cesantías | C41: 20000 | H41: 15 | I41: 16 | J41: =N40 -> 21390717 | K41: =$F$9 -> 1097083.5 | L41: =J41*$F$7 -> 230097.34 | M41: =K41-L41 -> 866986.16 | N41: =J41-M41 -> 20523731 | O41: Pendiente | P41: 15 | Q41: 16 | R41: =V40 -> 21809612 | S41: =$S$27 -> 1157921.2 | T41: =R41*(AVERAGE($F$15,$F$23,$F$31,(1+$F$37)^(1/12)-1,(1+$F$38)^(1/12)-1,(1+$F$39)^(1/12)-1,(1+$F$40)^(1/12)-1)) -> 303963.39 | U41: =S41-T41 -> 853957.81 | V41: =R41-U41 -> 20955654 | W41: Pendiente
...

Sheet Cuentas T
B1: Cuentas T mensuales y consolidadas - abril a diciembre 2026
B3: Abril 2026 (M1)
B4: Caja General | E4: Reserva de Imprevistos | H4: Equipos de cómputo (base)
B5: 110505 | E5: 111005 | H5: 152405
B6: Débito | C6: Crédito | E6: Débito | F6: Crédito | H6: Débito | I6: Crédito
B7: =Proyecciones!$F$2 -> 21735329 | C7: =Proyecciones!$C$3 -> 1890622.5 | E7: =Proyecciones!$C$3 -> 1890622.5 | H7: =Proyecciones!$AA$4 -> 21881849
B8: =Proyecciones!$F$5 -> 32602994 | C8: =Proyecciones!$C$5 -> 26039400
C9: =Proyecciones!$C$6 -> 150000
C10: =Proyecciones!$C$7 -> 1050000
C11: =Proyecciones!$C$8 -> 25208300
B15: =SUM(B7:B14) -> 54338322 | C15: =SUM(C7:C14) -> 54338323 | E15: =SUM(E7:E14) -> 1890622.5 | F15: =SUM(F7:F14) -> 0 | H15: =SUM(H7:H14) -> 21881849 | I15: =SUM(I7:I14) -> 0
B16: =IF((B15-C15)>0,B15-C15,"") | C16: =IF((C15-B15)>0,C15-B15,"") -> 7.4505806e-09 | E16: =IF((E15-F15)>0,E15-F15,"") -> 1890622.5 | F16: =IF((F15-E15)>0,F15-E15,"") | H16: =IF((H15-I15)>0,H15-I15,"") -> 21881849 | I16: =IF((I15-H15)>0,I15-H15,"")
B17: IVA descontable equipos | E17: Mouses ergonómicos (base) | H17: Monitores (base)
B18: 135515 | E18: 152410 | H18: 152415
B19: Débito | C19: Crédito | E19: Débito | F19: Crédito | H19: Débito | I19: Crédito
B20: =Proyecciones!$AB$7 -> 4349147.9 | E20: =Proyecciones!$AA$5 -> 126050.42 | H20: =Proyecciones!$AA$6 -> 882352.94
B28: =SUM(B20:B27) -> 4349147.9 | C28: =SUM(C20:C27) -> 0 | E28: =SUM(E20:E27) -> 126050.42 | F28: =SUM(F20:F27) -> 0 | H28: =SUM(H20:H27) -> 882352.94 | I28: =SUM(I20:I27) -> 0
B29: =IF((B28-C28)>0,B28-C28,"") -> 4349147.9 | C29: =IF((C28-B28)>0,C28-B28,"") | E29: =IF((E28-F28)>0,E28-F28,"") -> 126050.42 | F29: =IF((F28-E28)>0,F28-E28,"") | H29: =IF((H28-I28)>0,H28-I28,"") -> 882352.94 | I29: =IF((I28-H28)>0,I28-H28,"")
B30: Obligación financiera Bancolombia | E30: Capital social | H30: Costos fijos operacionales
B31: 210505 | E31: 310505 | H31: 513595
B32: Débito | C32: Crédito | E32: Débito | F32: Crédito | H32: Débito | I32: Crédito
C33: =Proyecciones!$F$5 -> 32602994 | F33: =Proyecciones!$F$2 -> 21735329 | H33: =Proyecciones!$Z$14 -> 25208300
B41: =SUM(B33:B40) -> 0 | C41: =SUM(C33:C40) -> 32602994 | E41: =SUM(E33:E40) -> 0 | F41: =SUM(F33:F40) -> 21735329 | H41: =SUM(H33:H40) -> 25208300 | I41: =SUM(I33:I40) -> 0
B42: =IF((B41-C41)>0,B41-C41,"") | C42: =IF((C41-B41)>0,C41-B41,"") -> 32602994 | E42: =IF((E41-F41)>0,E41-F41,"") | F42: =IF((F41-E41)>0,F41-E41,"") -> 21735329 | H42: =IF((H41-I41)>0,H41-I41,"") -> 25208300 | I42: =IF((I41-H41)>0,I41-H41,"")
B44: Mayo 2026
B45: Caja General | E45: Ingresos operacionales | H45: Costos fijos operacionales
B46: 110505 | E46: 417595 | H46: 513595
B47: Débito | C47: Crédito | E47: Débito | F47: Crédito | H47: Débito | I47: Crédito
B48: =Proyecciones!$AA$13 -> 35550000 | C48: =Proyecciones!$AA$14 -> 25208300 | F48: =Proyecciones!$AA$13 -> 35550000 | H48: =Proyecciones!$AA$14 -> 25208300
C49: =Proyecciones!$AA$15 -> 1777500
C50: =Proyecciones!$AA$18 -> 1097083.5
B56: =SUM(B48:B55) -> 35550000 | C56: =SUM(C48:C55) -> 28082884 | E56: =SUM(E48:E55) -> 0 | F56: =SUM(F48:F55) -> 35550000 | H56: =SUM(H48:H55) -> 25208300 | I56: =SUM(I48:I55) -> 0
B57: =IF((B56-C56)>0,B56-C56,"") -> 7467116.5 | C57: =IF((C56-B56)>0,C56-B56,"") | E57: =IF((E56-F56)>0,E56-F56,"") | F57: =IF((F56-E56)>0,F56-E56,"") -> 35550000 | H57: =IF((H56-I56)>0,H56-I56,"") -> 25208300 | I57: =IF((I56-H56)>0,I56-H56,"")
B58: Costos variables / comisiones | E58: Gastos financieros Bancolombia | H58: Obligación financiera Bancolombia
B59: 613595 | E59: 530520 | H59: 210505
B60: Débito | C60: Crédito | E60: Débito | F60: Crédito | H60: Débito | I60: Crédito
B61: =Proyecciones!$AA$15 -> 1777500 | E61: =Proyecciones!$AA$16 -> 350706.43 | H61: =Proyecciones!$AA$17 -> 746377.07
B69: =SUM(B61:B68) -> 1777500 | C69: =SUM(C61:C68) -> 0 | E69: =SUM(E61:E68) -> 350706.43 | F69: =SUM(F61:F68) -> 0 | H69: =SUM(H61:H68) -> 746377.07 | I69: =SUM(I61:I68) -> 0
B70: =IF((B69-C69)>0,B69-C69,"") -> 1777500 | C70: =IF((C69-B69)>0,C69-B69,"") | E70: =IF((E69-F69)>0,E69-F69,"") -> 350706.43 | F70: =IF((F69-E69)>0,F69-E69,"") | H70: =IF((H69-I69)>0,H69-I69,"") -> 746377.07 | I70: =IF((I69-H69)>0,I69-H69,"")
B72: Junio 2026
...

Sheet Rentabilidad del inversor
B2: Fuentes | C2: Monto | D2: Participación | E2: Costo Financiero | F2: Impuestos | G2: WACC | I2: TIR
B3: Pasivo | C3: =Proyecciones!F5 -> 32602994 | D3: =C3/(C3+C4) -> 0.6 | E3: =0.137 -> 0.137 | F3: 0.35 | G3: =D3*E3*(1-F3)+D4*E4 -> 0.11043 | H3: < | I3: 0.1506
B4: Patrimonio | C4: =B13 -> 21735329 | D4: =C4/(C4+C3) -> 0.4 | E4: 0.1425
B6: Dado que la tasa de interés libre de riesgo del inversionista es menor a la Tasa Interna de Retorno para el primer periodo el proyecto se considera conveniente, atractivo para el inversor
B12: Inversión Inicial | C12: Ingreso 1 | D12: Ingreso 2 | E12: Ingreso 3 | F12: Ingreso 4 | G12: Ingreso 5 | H12: Ingreso 6 | I12: Ingreso 7 | J12: Ingreso 8
B13: 21735329 | C13: =Proyecciones!$Q$15 -> 4853625.7 | D13: =Proyecciones!$Q$15 -> 4853625.7 | E13: =Proyecciones!$Q$15 -> 4853625.7 | F13: =Proyecciones!$Q$15 -> 4853625.7 | G13: =Proyecciones!$Q$15 -> 4853625.7 | H13: =Proyecciones!$Q$15 -> 4853625.7 | I13: =Proyecciones!$Q$15 -> 4853625.7 | J13: =Proyecciones!$Q$15 -> 4853625.7
B14: Valor Presente | C14: =C13/((1+$G$3)^1) -> 4370942.5 | D14: =D13/((1+$G$3)^2) -> 3936261.2 | E14: =E13/((1+$G$3)^3) -> 3544808.1 | F14: =F13/((1+$G$3)^4) -> 3192284.1 | G14: =G13/((1+$G$3)^5) -> 2874818 | H14: =H13/((1+$G$3)^6) -> 2588923.2 | I14: =I13/((1+$G$3)^7) -> 2331460.1 | J14: =J13/((1+$G$3)^8) -> 2099601.1
B15: Valor Presente Neto | F15: =-B13+SUM(C14:J14) -> 3203769.2
B17: Análisis de sensibilidad Pesimista (-10% en ventas): Nuevo VPN = | F17: =F21 -> 709859.42
B18: Inversión Inicial | C18: Ingreso 1 | D18: Ingreso 2 | E18: Ingreso 3 | F18: Ingreso 4 | G18: Ingreso 5 | H18: Ingreso 6 | I18: Ingreso 7 | J18: Ingreso 8
B19: 21735329 | C19: =C13*0.9 -> 4368263.2 | D19: =D13*0.9 -> 4368263.2 | E19: =E13*0.9 -> 4368263.2 | F19: =F13*0.9 -> 4368263.2 | G19: =G13*0.9 -> 4368263.2 | H19: =H13*0.9 -> 4368263.2 | I19: =I13*0.9 -> 4368263.2 | J19: =J13*0.9 -> 4368263.2
B20: Valor Presente | C20: =C19/((1+$G$3)^1) -> 3933848.3 | D20: =D19/((1+$G$3)^2) -> 3542635.1 | E20: =E19/((1+$G$3)^3) -> 3190327.3 | F20: =F19/((1+$G$3)^4) -> 2873055.7 | G20: =G19/((1+$G$3)^5) -> 2587336.2 | H20: =H19/((1+$G$3)^6) -> 2330030.9 | I20: =I19/((1+$G$3)^7) -> 2098314 | J20: =J19/((1+$G$3)^8) -> 1889641
B21: Valor Presente Neto | F21: =-B19+SUM(C20:J20) -> 709859.42
B23: Análisis de sensibilidad Optimista (+10% en ventas): Nuevo VPN = | F23: =F27 -> 5697679.1
B24: Inversión Inicial | C24: Ingreso 1 | D24: Ingreso 2 | E24: Ingreso 3 | F24: Ingreso 4 | G24: Ingreso 5 | H24: Ingreso 6 | I24: Ingreso 7 | J24: Ingreso 8
B25: 21735329 | C25: =C13*1.1 -> 5338988.3 | D25: =D13*1.1 -> 5338988.3 | E25: =E13*1.1 -> 5338988.3 | F25: =F13*1.1 -> 5338988.3 | G25: =G13*1.1 -> 5338988.3 | H25: =H13*1.1 -> 5338988.3 | I25: =I13*1.1 -> 5338988.3 | J25: =J13*1.1 -> 5338988.3
B26: Valor Presente | C26: =C25/((1+$G$3)^1) -> 4808036.8 | D26: =D25/((1+$G$3)^2) -> 4329887.3 | E26: =E25/((1+$G$3)^3) -> 3899288.9 | F26: =F25/((1+$G$3)^4) -> 3511512.5 | G26: =G25/((1+$G$3)^5) -> 3162299.8 | H26: =H25/((1+$G$3)^6) -> 2847815.5 | I26: =I25/((1+$G$3)^7) -> 2564606.1 | J26: =J25/((1+$G$3)^8) -> 2309561.2
B27: Valor Presente Neto | F27: =-B25+SUM(C26:J26) -> 5697679.1
B29: Rentabilidad Financiera - ROE | F29: ='Situación Financiera'!C16/'Situación Financiera'!C17 -> 0.54914757
B30: Rentabilidad Económica - ROA | F30: ='Situación Financiera'!C16/'Situación Financiera'!C10 -> 0.35482487
B32: El proyecto es sensible a un cambio en las ventas tanto al alza como a la baja, más en este segundo, lo que implica que debe ser de riguroso manejo el plan comercial de la empresa.

Sheet Flujos De Efectivo
B2: Estado de Flujos de Efectivo Proyectado a Diciembre de 2026
B3: Cobros por ventas | C3: =SUM(Proyecciones!Z13:AH13) -> 284400000
B4: Pagos de costos fijos | C4: =-SUM(Proyecciones!Z14:AH14) -> -2.268747e+08
B5: Pagos de costos Variables | C5: =-SUM(Proyecciones!Z15:AH15) -> -14220000
B6: Pagos de gastos financieros | C6: =-SUM(Proyecciones!Z16:AH16) -> -2575946.2
B7: Pagos de impuesto de renta | C7: =-SUM(Proyecciones!Z20:AH20) -> -14255274
B8: Flujo neto de operación | C8: =C3+C4+C5+C6+C7 -> 26474080
B9: Compra de activos iniciales | C9: =Proyecciones!C3+Proyecciones!C5+Proyecciones!C6+Proyecciones!C7 -> 29130022
B10: Flujo neto de inversión | C10: =-C9 -> -29130022
B11: Aportes de socios | C11: =Proyecciones!F2 -> 21735329
B12: Desembolso del crédito | C12: =Proyecciones!F5 -> 32602994
B13: Abono a capital de Crédito | C13: =-SUM(Proyecciones!Z17:AH17) -> -6200721.8
B14: Flujo neto de financiación | C14: =C11+C12+C13 -> 48137601
B15: Efectivo inicial | C15: 0
B16: Efectivo final | C16: =C8+C10+C14 -> 45481658
B17: Aumento neto de efectivo | C17: =C16 -> 45481658

Sheet Resultados Integrales
B2: Estado de Resultados Integrales Proyectado a diciembre 2026
B3: Ingresos operacionales | C3: =SUM(Proyecciones!Z13:AH13) -> 284400000
B4: (-) Costos fijos del período | C4: =-SUM(Proyecciones!Z14:AH14) -> -2.268747e+08
B5: (-) Costos variables del período | C5: =-SUM(Proyecciones!Z15:AH15) -> -14220000
B6: Utilidad operativa | C6: =C3+C4+C5 -> 43305300
B7: (-) Gastos financieros | C7: =-SUM(Proyecciones!Z16:AH16) -> -2575946.2
B8: Utilidad antes de impuestos | C8: =C6+C7 -> 40729354
B9: (-) Impuesto de renta | C9: =-SUM(Proyecciones!Z20:AH20) -> -14255274
B10: Utilidad neta acumulada | C10: =C8+C9 -> 26474080

Sheet Situación Financiera
B2: Estado de Situación Financiera proyectado a Diciembre de 2026
B3: Activos
B4: Efectivo y equivalentes | C4: ='Flujos De Efectivo'!C17 -> 45481658
B5: Reservas de Imprevistos | C5: =Proyecciones!C3 -> 1890622.5
B6: Equipos de cómputo (base) | C6: =Proyecciones!AA4 -> 21881849
B7: Mouses Ergonómicos (base) | C7: =Proyecciones!AA5 -> 126050.42
B8: Monitores (base) | C8: =Proyecciones!AA6 -> 882352.94
B9: IVA descontable equipos | C9: =Proyecciones!AB7 -> 4349147.9
B10: Total activos | C10: =SUM(C4:C9) -> 74611681
B11: Pasivos
B12: Obligación financiera | C12: =Proyecciones!N34 -> 26402272
B13: Total pasivos | C13: =C12 -> 26402272
B14: Patrimonio
B15: Capital social | C15: ='Flujos De Efectivo'!C11 -> 21735329
B16: Resultados acumulados | C16: ='Resultados Integrales'!C10 -> 26474080
B17: Total patrimonio | C17: =C15+C16 -> 48209409

Sheet Estudio de mercado
B2: Estructura de mercado | D2: ZUMIA Solutions S.A.S. opera en una estructura de mercado de competencia monopolística. Este tipo de mercado se caracteriza por la existencia de numerosos oferentes que prestan servicios similares, pero diferenciados a través de elementos como calidad, precio, marca, rapidez de entrega y valor agregado. En el sector de servicios digitales y desarrollo web, no existe un único proveedor dominante y los clientes tienen libertad para elegir entre múltiples opciones. ZUMIA se diferencia al enfocarse exclusivamente en micronegocios y pequeñas empresas con baja madurez digital, ofreciendo soluciones estandarizadas, rápidas y con acompañamiento posterior.
B10: Demanda | D10: ZUMIA Solutions S.A.S. opera en una estructura de mercado de competencia monopolística. Este tipo de mercado se caracteriza por la existencia de numerosos oferentes que prestan servicios similares, pero diferenciados a través de elementos como calidad, precio, marca, rapidez de entrega y valor agregado. En el sector de servicios digitales y desarrollo web, no existe un único proveedor dominante y los clientes tienen libertad para elegir entre múltiples opciones. ZUMIA se diferencia al enfocarse exclusivamente en micronegocios y pequeñas empresas con baja madurez digital, ofreciendo soluciones estandarizadas, rápidas y con acompañamiento posterior.
B18: Oferta | D18: ZUMIA Solutions S.A.S. opera en una estructura de mercado de competencia monopolística. Este tipo de mercado se caracteriza por la existencia de numerosos oferentes que prestan servicios similares, pero diferenciados a través de elementos como calidad, precio, marca, rapidez de entrega y valor agregado. En el sector de servicios digitales y desarrollo web, no existe un único proveedor dominante y los clientes tienen libertad para elegir entre múltiples opciones. ZUMIA se diferencia al enfocarse exclusivamente en micronegocios y pequeñas empresas con baja madurez digital, ofreciendo soluciones estandarizadas, rápidas y con acompañamiento posterior. El análisis de la competencia se encuentra en las celdas posteriores | K18: Empresa (Razón social) | L18: NIT | M18: Dirección | N18: Ciudad | O18: Dpto. | P18: Representante legal | Q18: Ventas (últ. año) | R18: Año fiscal | S18: Actividad principal | T18: Otras actividades | U18: Estado | V18: Año de constitución
K19: Evolutech Consulting S.A.S. | L19: 901913314 | M19: Carrera 116 B 78B 62 Torre 6, Apartament | N19: Bogotá D.C. | O19: Bogotá D.C. | P19: Jonnathan Steven Nino Pena [901913314_...erfil EMIS | PDF] | Q19: Jonnathan Steven Nino Pena [901913314_...erfil EMIS | PDF] | R19: Jonnathan Steven Nino Pena [901913314_...erfil EMIS | PDF] | S19: Jonnathan Steven Nino Pena [901913314_...erfil EMIS | PDF] | T19: Jonnathan Steven Nino Pena [901913314_...erfil EMIS | PDF] | U19: Jonnathan Steven Nino Pena [901913314_...erfil EMIS | PDF] | V19: Jonnathan Steven Nino Pena [901913314_...erfil EMIS | PDF]
K20: 10Pearls Colombia S.A.S. | L20: 901252874 | M20: Carrera 30 No. 7 Aa 207 | N20: Medellín | O20: Antioquia | P20: Lean Case S.A.S. (Rep. legal) [901252874_...erfil EMIS | PDF] | Q20: 7.079 millones COP (Total Operating Revenue) [901252874_...erfil EMIS | PDF] | R20: 2024 [901252874_...erfil EMIS | PDF] | S20: Diseño de sistemas de cómputo y servicios relacionados (54151) [901252874_...erfil EMIS | PDF] | T20: — | U20: Activa/Operational [901252874_...erfil EMIS | PDF] | V20: 2019 (07-feb) [901252874_...erfil EMIS | PDF]
K21: Platino Grupo Empresarial S.A.S. | L21: 900156896 | M21: Calle 125 21 A 27 Of. 302 | N21: Bogotá D.C. | O21: Bogotá D.C. | P21: Álvaro Gómez Maya [900156896_...erfil EMIS | PDF] | Q21: 1.864 millones COP (Total Operating Revenue) [900156896_...erfil EMIS | PDF] | R21: 2024 [900156896_...erfil EMIS | PDF] | S21: Otras actividades relacionadas con la intermediación de crédito (52239) [900156896_...erfil EMIS | PDF] | T21: — | U21: Activa/Operational [900156896_...erfil EMIS | PDF] | V21: 2007 (14-jun) [900156896_...erfil EMIS | PDF]
K22: Since Agencia en Innovación y Marketing Digital S.A.S. | L22: 901451271 | M22: Calle 23 # 81–39 Of. 02 | N22: Fusagasugá | O22: Cundinamarca | P22: Juan Carlos Gamboa | Q22: 584 millones COP (Total Operating Revenue) | R22: 2024 | S22: Publicidad (CIIU 7310) [bogota.inf...nfo.com.co] | T22: Diseño (7410), fotografía (7420), creación audiovisual (9004) [bogota.inf...nfo.com.co] | U22: Activa [bogota.inf...nfo.com.co] | V22: 2021 [bogota.inf...nfo.com.co]
B23: Clientes | D23: Los clientes potenciales de ZUMIA Solutions se encuentran principalmente en zonas urbanas de Bogotá D.C., especialmente en sectores comerciales con alta concentración de micronegocios. Estos clientes corresponden a negocios con entre uno y diez empleados, propiedad de jóvenes emprendedores entre 18 y 35 años. Desde el punto de vista psicográfico, se trata de empresarios con orientación práctica, interesados en soluciones rápidas, claras y económicas. Conductualmente, son dueños de negocios que perciben potencial de crecimiento, pero carecen de conocimientos técnicos en marketing digital y desarrollo web.
B31: Mercado Objetivo y Ubicación Geográfica | D31: El mercado objetivo de ZUMIA Solutions está conformado por micronegocios y pequeñas empresas ubicadas en Bogotá D.C. que no cuentan con página web profesional y desean fortalecer su presencia digital para aumentar sus ventas y mejorar su imagen corporativa. Los nichos principales incluyen servicios locales como inmobiliarias, abogados, contadores, barberías, gimnasios, autolavados y emprendimientos.
B39: Características del producto | D39: ZUMIA Solutions ofrece la creación de páginas web tipo landing page con las siguientes características técnicas: diseño profesional y responsive, dominio propio, carga rápida, estructura optimizada para conversión, botones de contacto directo (WhatsApp, llamadas y formularios), branding básico, diagnóstico digital gratuito y acompañamiento antes y después de la entrega. El servicio se encuentra estandarizado para reducir tiempos de implementación y costos.
B47: Competencia | D47: La competencia de ZUMIA Solutions se divide en directa e indirecta. La competencia directa incluye agencias digitales pequeñas y freelancers que ofrecen servicios personalizados. La competencia indirecta está conformada por plataformas automatizadas como Wix, Shopify y GoDaddy. ZUMIA se diferencia por su enfoque exclusivo en micronegocios, claridad en precios, rapidez y acompañamiento.
B55: Investigación de mercado | D55: En Bogotá existen más de 500.000 micronegocios. Para efectos del proyecto se considera como mercado accesible inicial el 5 %, equivalente a aproximadamente 25.000 negocios. La muestra sugerida para validación inicial es de 100 micronegocios.
B63: Plan de Marketing | D63: El plan de marketing de ZUMIA se basa en una propuesta de valor clara, usando como principales herramientas el diagnóstico digital gratuito, contenido educativo en redes sociales, alianzas estratégicas, marketing de referidos y presencia web propia. El nombre comercial es ZUMIA Solutions y su slogan es “Presencia digital que vende”.

Sheet Estudio Técnico
B2: Proceso Productivo | D2: El proceso de producción, resumido en el cronograma de actividades tipo Diagrama de Gant, seguirá los siguientes pasos: Adquisición de clientes potenciales a cargo del área Comercial - Solicitud de elementos requeridos por parte del cliente (Logos, información, secciones requeridas) - Pago del 50% del servicio - Presentación de propuesta inicial al cliente desarrollada por los programadores del área Operativa - Rondas de Ajustes (máximo 3) a la propuesta inicial según requerimientos del cliente - Pago del 50% restante del servicio - Implementación web del diseño en un dominio propiedad del cliente - Contabilidad del proceso.
B10: Estructura de Costos | D10: Zumia tendrá los costos fijos mensuales especificados en la página "Proyecciones", los cuales constan de los salarios a los trabajadores, obligaciones contractuales, parafiscales e insumos mensuales amortizados, por el lado de lso costos variables, tendremos un 5% de comisión para los encargados de vender el servicio a los clientes, las bases de datos, programas y requerimientos tambien han sido contabilizados dentro de lso costos totales, todo esto dando un punto de equilibrio inicial de 32 unidades vendidas por mes, este sería el tamaño mínimo
B18: Recursos físicos requeridos | D18: Cada trabajador de Zumia contará con un computador personal propiedad de la empresa y un mouse ergonómico para sus operaciones en cada, los programadores tendrán además de ello una pantalla inhalambrica para sus labores
B26: Capacidad de producción | D26: Cada programador tendrá la capacidad de crear 20 páginas web tipo landing como máximo al mes, sin embargo se usará el 75% de su capacidad laboral para tener un margen de imprevistos en el que cada uno de elos produzca 3 páginas, con un total mensual a nivel óptimo de 45 con 3 programadores inicialmente

Sheet Estudio Administrativo
B2: Misión | D2: Impulsar micronegocios y pymes a aumentar sus ventas mediante soluciones web y marketing digital claras, rápidas y enfocadas en la conversión.
B7: Visión | D7: Ser una empresa reconocida a nivel nacional por la implementación eficiente de soluciones digitales, con un modelo escalable y orientado a resultados.digital claras, rápidas y enfocadas en la conversión.
B12: Objetivo General | D12: Desarrollar y consolidar una empresa de servicios digitales que permita mejorar la presencia online de sus clientes y generar crecimiento sostenible.digital claras, rápidas y enfocadas en la conversión.
B17: Objetivos Específicos | D17: Diseñar páginas web funcionales y optimizadas. Reducir tiempos de entrega mediante procesos estandarizados. Captar clientes mediante estrategias digitales. Garantizar rentabilidad y sostenibilidad del negocio.digital claras, rápidas y enfocadas en la conversión.
B22: Metas | D22: Alcanzar un volumen de 45 proyectos mensuales. Lograr punto de equilibrio en el corto plazo (36 servicios). Recuperar la inversión en aproximadamente 10–12 meses. digital claras, rápidas y enfocadas en la conversión.
B27: Estrategias | D27: Estrategia de diferenciación basada en rapidez y personalización. Uso de marketing digital (Meta Ads, Google Ads). Estandarización del servicio tipo landing page. Precios competitivos orientados a micronegocios.
B32: Estructura Organizacional | D32: Gerente general. Área operativa (3 programadores). Área comercial (1 asesor). Área financiera (1 contador).
B37: Manual Operativo del Area Técnica | D37: Desarrollo de páginas web bajo estándares definidos. Uso de herramientas tecnológicas como React, GitHub y Cloudflare. Cumplimiento de tiempos de entrega establecidos.
B42: Manual Operativo del Area Comercial | D42: Captación de clientes. Gestión de pagos (50% inicial y 50% final). Atención y seguimiento al cliente.
B47: Manual Operativo del Area Administrativa | D47: Supervisión de actividades. Coordinación entre áreas. Control de procesos internos.
B52: Manual Operativo del Area Financiera | D52: Registro contable de operaciones. Control de ingresos y egresos. Gestión de obligaciones tributarias
B57: Gestión de comunicaciones | D57: Comunicación interna WhatsApp empresarial. Reuniones semanales de seguimiento. Comunicación externa Correo corporativo.
... B67: Políticas de sueldo | D67: Personal administrativo: salario mínimo legal vigente más auxilio de conectividad. Programadores: 1.5 salarios mínimos. Comercial: sueldo base más comisión Inclusión de prestaciones sociales, seguridad social y parafiscales conforme a la normativa laboral vigente.

Sheet Estudio Legal

Sheet Estudio Ambiental
B2: Descripción del Proyecto | D2: Zumia Solutions es una empresa de servicios digitales dedicada al desarrollo de páginas web y soluciones tecnológicas. Su operación es 100% virtual, lo que implica un bajo impacto ambiental en comparación con actividades industriales, al no requerir procesos productivos físicos ni uso intensivo de recursos naturales.
B7: Linea de trabajo Base | D7: El proyecto se desarrolla en un entorno urbano (Bogotá) bajo un modelo de trabajo remoto, sin infraestructura física significativa. Condiciones relevantes: Bajo consumo de recursos naturales. Uso principal de energía eléctrica para equipos tecnológicos. No generación de residuos industriales.
B12: Impactos ambientales Positivos | D12: Reducción del uso de papel mediante digitalización de procesos. Disminución de desplazamientos por trabajo remoto. Apoyo a la transformación digital de empresas.
B17: Impactos ambientales Negativos | D17: Consumo de energía eléctrica. Generación de residuos electrónicos (equipos tecnológicos).
B22: Matriz de impacto ambiental
B37: Medidas de manejo ambiental | D37: Uso eficiente de energía en equipos tecnológicos. Promoción del trabajo remoto para reducir emisiones. Digitalización total de documentos. Disposición adecuada de residuos electrónicos. Uso de herramientas tecnológicas sostenibles.
B42: Seguimiento y Monitoreo | D42: Revisión del consumo energético. Control del uso de recursos digitales. Evaluación de prácticas sostenibles internas.
B47: Conclusión Ambiental | D47: El proyecto presenta un impacto ambiental bajo, con predominancia de efectos positivos asociados a la digitalización y reducción de procesos físicos. La implementación de buenas prácticas sostenibles permite mitigar los impactos negativos y fortalecer el enfoque ambiental de la empresa.

Sheet D-O-F-A
G2: Fortalezas | H2: Debilidades
G3: Amenazas | H3: Oportunidades
B5: 1. Procesos estandarizados: entrega de landing pages en un promedio de 5 días hábiles mediante un diagrama de Gantt optimizado. 2. Estructura legal S.A.S.: constitución flexible que protege el patrimonio de los socios y reduce gastos administrativos. 3. Conocimiento técnico: dominio de herramientas como React, HTML, CSS, GitHub y Cloudflare. 4. Eficiencia operativa: modelo de trabajo remoto que reduce costos fijos y apoya la economía verde (baja huella de carbono). 5. Bajos costos iniciales: inversión controlada enfocada en activos tecnológicos y capital de trabajo inicial. | H5: 1. Posicionamiento de marca: falta de reconocimiento inicial en el mercado por ser una empresa nueva. 2. Recursos limitados: capacidad de producción limitada por el tamaño del equipo (3 programadores iniciales). 3. Dependencia de clientes: sensibilidad financiera ante la captación de los primeros proyectos para alcanzar el punto de equilibrio. 4.Sensibilidad al precio: los clientes pueden ser reticentes al pago frente a competidores de baja calidad y bajo costo.
B11: 1. Alta competencia: rivalidad con gigantes globales (Shopify, Wix) y agencias locales o freelancers. 2. Obsolescencia técnica: cambios tecnológicos rápidos que exigen actualización constante en lenguajes y herramientas de IA. 3. Incertidumbre económica: posibles recortes de presupuesto en las pymes ante crisis o fluctuaciones del mercado. 4. Contenido del cliente: riesgo de proyectos fallidos si el cliente no entrega material de calidad o tiene un negocio no rentable. | H11: 1. Brecha digital masiva: el 50.4% de los micronegocios en Colombia no usan internet; hay 500.000 clientes potenciales solo en Bogotá. 2. Crecimiento del sector: tendencia de crecimiento del 12% anual en descargas y servicios digitales en la región. 3. Financiación estratégica: acceso a tasas competitivas (ej. Bancolombia 13.7% EA) para apalancar el crecimiento. 4. Economías naranja/verde: el modelo digital y remoto permite acceder a beneficios por incentivos ambientales y creativos.

Sheet GANNT
B2: Gannt de consolidación | C2: Responsable | D2: Semana 1 | E2: Semana 2 | F2: Semana 3 | G2: Semana 4 | H2: Semana 5
B4: Definición estratégica (objeto social, modelo negocio, estructura) | C4: Gerencia | D4: X
B5: Validación de nombre y tipo societario | C5: Comercial | D5: X
B6: Redacción de estatutos y acuerdos internos | C6: Administración | D6: X
B7: Constitución legal (Cámara de Comercio) | C7: Comercial | E7: X
B8: Registro RUT y responsabilidades tributarias | C8: Comercial | E8: X
B9: Apertura cuenta bancaria empresarial | C9: Financiero | E9: X
B10: Implementación contable (software, plan de cuentas, NIIF) | C10: Financiero | F10: X
B11: Desarrollo activos digitales (web, branding básico) | C11: Operaciones | F11: X
B12: Estructura comercial (oferta, pricing, pipeline) | C12: Comercial | G12: X
B13: Gobierno y control (políticas internas, KPIs, flujo caja) | C13: Administración | G13: X
B15: Gannt de servicio vendido | C15: Responsable | D15: Día 1 | E15: Día 2 | F15: Día 3 | G15: Día 4 | H15: Día 5
B17: Captación del cliente | C17: Comercial | D17: X
B18: Recolección de requerimientos | C18: Comercial + Cliente | D18: X
B19: Pago inicial (50%) | C19: Comercial | E19: X
B20: Diseño inicial (UX/UI) | C20: Programadores | F20: X
B21: Desarrollo web (React/HTML/CSS) | C21: Programadores | F21: X
B22: Revisión y ajustes | C22: Programadores + Cliente | G22: X
B23: Pago final (50%) | C23: Comercial | H23: X
B24: Entrega e implementación | C24: Programadores | H24: X
B25: Registro contable | C25: Contador | D25: X
B26: Supervisión General | C26: Gerencia | D26: X

Sheet Hoja1

Sheet Indicadores
B2: Indicadores Financieros | G2: Indicadores Económicos
B3: Tasa Activa de mercado (Colocación) | G3: PIB a precios constantes de 2015 (Millones de pesos)
B4: Año | C4: Mes | D4: Valor | E4: Gráfico | F4: Efecto en Zumia | G4: Año | H4: Mes | I4: Valor | J4: Gráfico | K4: Efecto en Zumia
B5: 2024 | C5: Enero | D5: 18.56 | F5: La tasa activa desciende y luego repunta, lo que indica variaciones en el costo del crédito para empresas. Cuando es alta, disminuye la inversión en servicios. Para ZUMIA, implica que debe reducir percepción de riesgo del cliente, mostrando resultados rápidos. Prevención: ofrecer paquetes escalables (empezar con landing) y no forzar tickets altos en momentos de crédito caro. | G5: 2020 | H5: Trimestre 1 | I5: 208984 | K5: El PIB muestra crecimiento sostenido, lo que indica expansión económica. Esto favorece la inversión en digitalización. Sin embargo, el crecimiento no es uniforme, lo que implica posibles desaceleraciones. Para ZUMIA, es clave aprovechar fases de crecimiento para escalar clientes premium. Prevención: no asumir crecimiento permanente; mantener estructura flexible de costos y operación.
C6: Febrero | D6: 17.87 | H6: Trimestre 2 | I6: 179588
C7: Marzo | D7: 17.32 | H7: Trimestre 3 | I7: 202864
C8: Abril | D8: 17.25 | H8: Trimestre 4 | I8: 226464
C9: Mayo | D9: 17.09 | G9: 2021 | H9: Trimestre 1 | I9: 212119
C10: Junio | D10: 16.38 | H10: Trimestre 2 | I10: 212672
C11: Julio | D11: 16.35 | H11: Trimestre 3 | I11: 229894
C12: Agosto | D12: 15.87 | H12: Trimestre 4 | I12: 251559
C13: Septiembre | D13: 15.78 | G13: 2022 | H13: Trimestre 1 | I13: 229311
C14: Octubre | D14: 15.38 | H14: Trimestre 2 | I14: 239014
C15: Noviembre | D15: 14.78 | H15: Trimestre 3 | I15: 246908
C16: Diciembre | D16: 14.1 | H16: Trimestre 4 | I16: 257422
B17: 2025 | C17: Enero | D17: 14.86 | G17: 2023 | H17: Trimestre 1 | I17: 235749
C18: Febrero | D18: 14.38 | H18: Trimestre 2 | I18: 239984
C19: Marzo | D19: 14.45 | H19: Trimestre 3 | I19: 245805
C20: Abril | D20: 14.91 | H20: Trimestre 4 | I20: 259305
C21: Mayo | D21: 14.34 | G21: 2024 | H21: Trimestre 1 | I21: 236500
C22: Junio | D22: 14.02 | H22: Trimestre 2 | I22: 243823
C23: Julio | D23: 14.39 | H23: Trimestre 3 | I23: 249752
C24: Agosto | D24: 14.26 | H24: Trimestre 4 | I24: 265415
C25: Septiembre | D25: 13.81 | G25: 2025 | H25: Trimestre 1 | I25: 242633
C26: Octubre | D26: 14.32 | H26: Trimestre 2 | I26: 248986
C27: Noviembre | D27: 14.21 | H27: Trimestre 3 | I27: 258738
C28: Diciembre | D28: 14 | H28: Trimestre 4 | I28: 271435
B29: 2026 | C29: Enero | D29: 14.63 | G29: Pendiente
C30: Febrero | D30: 15.07
C31: Marzo | D31: 15.96
B32: Tasa Pasiva de mercado (Captación) | G32: Inflación con base en los precios de 2018
B33: Año | C33: Mes | D33: Valor | E33: Gráfico | F33: Efecto en Zumia | G33: Año | H33: Mes | I33: Valor | J33: Gráfico | K33: Efecto en Zumia
B34: 2024 | C34: Enero | D34: 11.67 | F34: La tasa pasiva presenta una tendencia al alza reciente, lo que incentiva el ahorro sobre la inversión. Esto puede reducir la disposición de los negocios a gastar en servicios como desarrollo web. Para ZUMIA, el enfoque debe ser demostrar que la web no es gasto sino generador de ingresos. Prevención: reforzar el discurso de retorno y captar clientes con urgencia comercial. | G34: 2024 | H34: Enero | I34: 0.92 | K34: La inflación muestra volatilidad con picos importantes. Esto reduce el poder adquisitivo y aumenta la sensibilidad al precio. Para ZUMIA, implica que debe ser extremadamente claro en el valor que entrega. Prevención: mantener estructura de costos eficiente y evitar incrementos bruscos de precios. También ofrecer soluciones modulares que permitan al cliente invertir progresivamente.
C35: Febrero | D35: 11.04 | H35: Febrero | I35: 1.09
C36: Marzo | D36: 10.44 | H36: Marzo | I36: 0.7
C37: Abril | D37: 10.47 | H37: Abril | I37: 0.59
C38: Mayo | D38: 10.2 | H38: Mayo | I38: 0.43
C39: Junio | D39: 10.83 | H39: Junio | I39: 0.32
C40: Julio | D40: 10.45 | H40: Julio | I40: 0.2
C41: Agosto | D41: 10 | H41: Agosto | I41: 0
...
